Workbook

Sheet Productie
A1: Oogstdatum | B1: Oogstjaar | C1: Perceel | D1: Ras | E1: Tonnen | F1: Koeling of | G1: Datum laatste bespuiting | H1: Middel en dosering/ha | I1: Veiligheidstermijn (dgn.) | J1: Opmerkingen
A2: 42975 | B2: 2017 | C2: 3 | D2: Elstar | E2: 2.1 | F2: Afgezet | G2: 42958 | H2: Bellis 0,8 kg/ha | I2: 7
A3: 42976 | B3: 2017 | C3: 3 | D3: Elstar | E3: 4.8 | F3: Afgezet | G3: 42958 | H3: Bellis 0,8 kg/ha | I3: 7
A4: 42977 | B4: 2017 | C4: 3 | D4: Elstar | E4: 4.8 | F4: Afgezet | G4: 42958 | H4: Bellis 0,8 kg/ha | I4: 7
A5: 42978 | B5: 2017 | C5: 3 | D5: Elstar | E5: 4.2 | F5: Afgezet | G5: 42958 | H5: Bellis 0,8 kg/ha | I5: 7
A6: 42980 | B6: 2017 | C6: 2b | D6: Elstar | E6: 1.8 | F6: Koeling | G6: 42958 | H6: Bellis 0,8 kg/ha | I6: 7
A7: 42984 | B7: 2017 | C7: 2b | D7: Elstar | E7: 4.5 | F7: Koeling | G7: 42958 | H7: Bellis 0,8 kg/ha | I7: 7
A8: 42985 | B8: 2017 | C8: 2b | D8: Elstar | E8: 2.7 | F8: Koeling | G8: 42958 | H8: Bellis 0,8 kg/ha | I8: 7
A9: 42985 | B9: 2017 | C9: 3 | D9: Elstar | E9: 3 | F9: Koeling | G9: 42958 | H9: Bellis 0,8 kg/ha | I9: 7
A10: 42987 | B10: 2017 | C10: 2b | D10: Golden | E10: 3.6 | F10: Koeling | G10: 42958 | H10: Bellis 0,8 kg/ha | I10: 7
A11: 42988 | B11: 2017 | C11: 2b | D11: Golden | E11: 1.2 | F11: Koeling | G11: 42958 | H11: Bellis 0,8 kg/ha | I11: 7
A12: 42988 | B12: 2017 | C12: 2a | D12: Golden | E12: 2.4 | F12: Koeling | G12: 42976 | H12: Bellis 0,8 kg/ha | I12: 7
A13: 42989 | B13: 2017 | C13: 3 | D13: Elstar | E13: 9.6 | F13: Koeling | G13: 42958 | H13: Bellis 0,8 kg/ha | I13: 7
A14: 42990 | B14: 2017 | C14: 3 | D14: Elstar | E14: 12 | F14: Koeling | G14: 42958 | H14: Bellis 0,8 kg/ha | I14: 7
A15: 42991 | B15: 2017 | C15: 3 | D15: Elstar | E15: 9.3 | F15: Koeling | G15: 42958 | H15: Bellis 0,8 kg/ha | I15: 7
A16: 42991 | B16: 2017 | C16: 2a | D16: Golden | E16: 1.2 | F16: Koeling | G16: 42976 | H16: Bellis 0,8 kg/ha | I16: 7
A17: 42992 | B17: 2017 | C17: 2c | D17: Golden | E17: 5.1 | F17: Koeling | G17: 42970 | H17: Captan 1,0 kg/ha | I17: 21
A18: 42992 | B18: 2017 | C18: 2a | D18: Golden | E18: 3.9 | F18: Koeling | G18: 42976 | H18: Bellis 0,8 kg/ha | I18: 7
A19: 42993 | B19: 2017 | C19: 6 | D19: Golden | E19: 10.2 | F19: Koeling | G19: 42981 | H19: Bellis 0,8 kg/ha | I19: 7
A20: 42994 | B20: 2017 | C20: 5 | D20: Golden | E20: 5.7 | F20: Koeling | G20: 42970 | H20: Captan 1,0 kg/ha | I20: 21
A21: 42995 | B21: 2017 | C21: 3 | D21: Elstar | E21: 3.3 | F21: Koeling | G21: 42958 | H21: Bellis 0,8 kg/ha | I21: 7
A22: 42995 | B22: 2017 | C22: 2ab,3,5,6 | D22: Kroet | E22: 0.9 | F22: Afgezet | G22: 42976 | H22: Bellis 0,8 kg/ha | I22: 7
A23: 42996 | B23: 2017 | C23: 4 | D23: Joly-Red | E23: 20.4 | F23: Koeling | G23: 42981 | H23: Bellis 0,8 kg/ha | I23: 7
A24: 42997 | B24: 2017 | C24: 4 | D24: Joly-Red | E24: 6.9 | F24: Koeling | G24: 42981 | H24: Bellis 0,8 kg/ha | I24: 7
A25: 42997 | B25: 2017 | C25: 4 | D25: Golden | E25: 1.5 | F25: Koeling | G25: 42981 | H25: Bellis 0,8 kg/ha | I25: 7
A26: 42997 | B26: 2017 | C26: 2b | D26: Elstar | E26: 4.8 | F26: Koeling | G26: 42958 | H26: Bellis 0,8 kg/ha | I26: 7
A27: 42998 | B27: 2017 | C27: 2b | D27: Elstar | E27: 11.1 | F27: Koeling | G27: 42958 | H27: Bellis 0,8 kg/ha | I27: 7
A28: 42998 | B28: 2017 | C28: 2a | D28: Golden | E28: 3.6 | F28: Koeling | G28: 42976 | H28: Bellis 0,8 kg/ha | I28: 7
A29: 42999 | B29: 2017 | C29: 2b | D29: Elstar | E29: 3 | F29: Koeling | G29: 42958 | H29: Bellis 0,8 kg/ha | I29: 7
A30: 42999 | B30: 2017 | C30: 2a | D30: Golden | E30: 12 | F30: Koeling | G30: 42976 | H30: Bellis 0,8 kg/ha | I30: 7
A31: 43000 | B31: 2017 | C31: 2a | D31: Golden | E31: 13.5 | F31: Koeling | G31: 42976 | H31: Bellis 0,8 kg/ha | I31: 7
A32: 43001 | B32: 2017 | C32: 2a | D32: Golden | E32: 8.7 | F32: Koeling | G32: 42976 | H32: Bellis 0,8 kg/ha | I32: 7
A33: 43001 | B33: 2017 | C33: 2ab,4 | D33: Kroet | E33: 1.8 | F33: Afgezet | G33: 42976 | H33: Bellis 0,8 kg/ha | I33: 7
A34: 43002 | B34: 2017 | C34: 2a | D34: Golden | E34: 5.4 | F34: Koeling | G34: 42976 | H34: Bellis 0,8 kg/ha | I34: 7
A35: 43003 | B35: 2017 | C35: 2a | D35: Golden | E35: 13.2 | F35: Koeling | G35: 42976 | H35: Bellis 0,8 kg/ha | I35: 7
A36: 43003 | B36: 2017 | C36: 6 | D36: Joly-Red | E36: 1.2 | F36: Koeling | G36: 42981 | H36: Bellis 0,8 kg/ha | I36: 7
A37: 43004 | B37: 2017 | C37: 2a | D37: Golden | E37: 1.2 | F37: Koeling | G37: 42976 | H37: Bellis 0,8 kg/ha | I37: 7
A38: 43004 | B38: 2017 | C38: 5 | D38: Golden | E38: 2.1 | F38: Koeling | G38: 42970 | H38: Captan 1,0 kg/ha | I38: 21
A39: 43004 | B39: 2017 | C39: 6 | D39: Joly-Red | E39: 15.6 | F39: Koeling | G39: 42981 | H39: Bellis 0,8 kg/ha | I39: 7
A40: 43005 | B40: 2017 | C40: 6 | D40: Joly-Red | E40: 21 | F40: Koeling | G40: 42981 | H40: Bellis 0,8 kg/ha | I40: 7
...

Sheet Afrekeningsoverzicht
A1: Categorie | B1: Subcategorie | C1: Rekening | D1: Omschrijving | E1: Boekjaar | F1: Bedrag | G1: OOP Breaburn | H1: OOP Delcorf | I1: OOP Elstar | J1: OOP Golden | K1: OOP Joly-Red | L1: OOP Jonagold | M1: OOP Jonagored | N1: OOP Junami | O1: OOP kroet/industrie appels | P1: OOP Milwa | Q1: Bedrag Genormaliseerd
A2: Aanvoer | B2: Opbrengsten | C2: Omzet | D2: Productomzet | E2: 2010 | F2: -191777.99 | Q2: =IF(F2<0,F2*-1,F2) -> 191777.99
A3: Aanvoer | B3: Balans | C3: Fust | D3: Fust eenmalig | E3: 2010 | F3: -6914.37 | Q3: =IF(F3<0,F3*-1,F3) -> 6914.37
A4: Aanvoer | B4: Balans | C4: Fust | D4: Fust meermalig | E4: 2010 | F4: -90708.9 | Q4: =IF(F4<0,F4*-1,F4) -> 90708.9
A5: Aanvoer | B5: Balans | C5: Fust | D5: Fust huur terugbet. | E5: 2010 | F5: -2783.05 | Q5: =IF(F5<0,F5*-1,F5) -> 2783.05
A6: Aanvoer | B6: Balans | C6: Verpakking | D6: Verpakkingskosten | E6: 2010 | F6: -1302.28 | Q6: =IF(F6<0,F6*-1,F6) -> 1302.28
A7: Aanvoer | B7: Balans | C7: Pallet | D7: Pallet eenmalig | E7: 2010 | F7: -630.18 | Q7: =IF(F7<0,F7*-1,F7) -> 630.18
A8: Aanvoer | B8: Balans | C8: Pallet | D8: Pallet meermalig | E8: 2010 | F8: -2694.78 | Q8: =IF(F8<0,F8*-1,F8) -> 2694.78
A9: Aanvoer | B9: Kosten | C9: Productheffing | D9: Productheffing | E9: 2010 | F9: 2019.23 | G9: 0 | H9: 0 | I9: ='Omzet&Prijs'!$C$3/SUM('Omzet&Prijs'!$C$2:$C$8)*$Q9 -> 842.70633 | J9: ='Omzet&Prijs'!$C$4/SUM('Omzet&Prijs'!$C$2:$C$8)*$Q9 -> 227.89369 | K9: 0 | L9: ='Omzet&Prijs'!$C$6/SUM('Omzet&Prijs'!$C$2:$C$8)*$Q9 -> 17.607917 | M9: ='Omzet&Prijs'!$C$5/SUM('Omzet&Prijs'!$C$2:$C$8)*$Q9 -> 356.7407 | N9: ='Omzet&Prijs'!$C$8/SUM('Omzet&Prijs'!$C$2:$C$8)*$Q9 -> 260.36956 | O9: ='Omzet&Prijs'!$C$7/SUM('Omzet&Prijs'!$C$2:$C$8)*$Q9 -> 285.09924 | P9: ='Omzet&Prijs'!$C$2/SUM('Omzet&Prijs'!$C$2:$C$8)*$Q9 -> 28.812565 | Q9: =IF(F9<0,F9*-1,F9) -> 2019.23
A10: Aanvoer | B10: Kosten | C10: Provisie | D10: Provisie lid | E10: 2010 | F10: =4537.88+3535.79 -> 8073.67 | G10: 0 | H10: 0 | I10: ='Omzet&Prijs'!$C$3/SUM('Omzet&Prijs'!$C$2:$C$8)*$Q10 -> 3369.469 | J10: ='Omzet&Prijs'!$C$4/SUM('Omzet&Prijs'!$C$2:$C$8)*$Q10 -> 911.20796 | K10: 0 | L10: ='Omzet&Prijs'!$C$6/SUM('Omzet&Prijs'!$C$2:$C$8)*$Q10 -> 70.403329 | M10: ='Omzet&Prijs'!$C$5/SUM('Omzet&Prijs'!$C$2:$C$8)*$Q10 -> 1426.3886 | N10: ='Omzet&Prijs'!$C$8/SUM('Omzet&Prijs'!$C$2:$C$8)*$Q10 -> 1041.0592 | O10: ='Omzet&Prijs'!$C$7/SUM('Omzet&Prijs'!$C$2:$C$8)*$Q10 -> 1139.9381 | P10: ='Omzet&Prijs'!$C$2/SUM('Omzet&Prijs'!$C$2:$C$8)*$Q10 -> 115.20389 | Q10: =IF(F10<0,F10*-1,F10) -> 8073.67
A11: Aanvoer | B11: Kosten | C11: Royalty Junami | D11: Royaltykst Junami | E11: 2010 | F11: 303.19 | G11: 0 | H11: 0 | I11: 0 | J11: 0 | K11: 0 | L11: 0 | M11: 0 | N11: =Q11 -> 303.19 | O11: 0 | P11: 0 | Q11: =IF(F11<0,F11*-1,F11) -> 303.19
A12: Aanvoer | B12: Kosten | C12: Promotie Junami | D12: Promotiekst Junami | E12: 2010 | F12: 1818.81 | G12: 0 | H12: 0 | I12: 0 | J12: 0 | K12: 0 | L12: 0 | M12: 0 | N12: =Q12 -> 1818.81 | O12: 0 | P12: 0 | Q12: =IF(F12<0,F12*-1,F12) -> 1818.81
A13: Aanvoer | B13: Kosten | C13: Productheffing Junami | D13: Heffingskst Junami | E13: 2010 | F13: 1515.73 | G13: 0 | H13: 0 | I13: 0 | J13: 0 | K13: 0 | L13: 0 | M13: 0 | N13: =Q13 -> 1515.73 | O13: 0 | P13: 0 | Q13: =IF(F13<0,F13*-1,F13) -> 1515.73
A14: Fust | B14: Balans | C14: Fust | D14: Fust m.m. Ingel. Aanvo. | E14: 2010 | F14: =-347.4+8846.36+85610.05+4865.82+2859.27+4323.2+80.17+-4323.2+-80.16 -> 101834.11 | Q14: =IF(F14<0,F14*-1,F14) -> 101834.11
A15: Kosten | B15: Balans | C15: Voorschot Junami | D15: Voorschot Junami | E15: 2010 | F15: 17850 | Q15: =IF(F15<0,F15*-1,F15) -> 17850
A16: Kosten | B16: Kosten | C16: Administratie | D16: Aanvoerboek | E16: 2010 | F16: 18.16 | G16: 0 | H16: 0 | I16: ='Omzet&Prijs'!$C$3/SUM('Omzet&Prijs'!$C$2:$C$8)*$Q16 -> 7.5789023 | J16: ='Omzet&Prijs'!$C$4/SUM('Omzet&Prijs'!$C$2:$C$8)*$Q16 -> 2.0495681 | K16: 0 | L16: ='Omzet&Prijs'!$C$6/SUM('Omzet&Prijs'!$C$2:$C$8)*$Q16 -> 0.15835728 | M16: ='Omzet&Prijs'!$C$5/SUM('Omzet&Prijs'!$C$2:$C$8)*$Q16 -> 3.2083572 | N16: ='Omzet&Prijs'!$C$8/SUM('Omzet&Prijs'!$C$2:$C$8)*$Q16 -> 2.3416407 | O16: ='Omzet&Prijs'!$C$7/SUM('Omzet&Prijs'!$C$2:$C$8)*$Q16 -> 2.5640477 | P16: ='Omzet&Prijs'!$C$2/SUM('Omzet&Prijs'!$C$2:$C$8)*$Q16 -> 0.25912659 | Q16: =IF(F16<0,F16*-1,F16) -> 18.16
A17: Kosten | B17: Kosten | C17: Administratie | D17: Administratiekosten | E17: 2010 | F17: 56.5 | G17: 0 | H17: 0 | I17: ='Omzet&Prijs'!$C$3/SUM('Omzet&Prijs'!$C$2:$C$8)*$Q17 -> 23.579735 | J17: ='Omzet&Prijs'!$C$4/SUM('Omzet&Prijs'!$C$2:$C$8)*$Q17 -> 6.3766849 | K17: 0 | L17: ='Omzet&Prijs'!$C$6/SUM('Omzet&Prijs'!$C$2:$C$8)*$Q17 -> 0.49268648 | M17: ='Omzet&Prijs'!$C$5/SUM('Omzet&Prijs'!$C$2:$C$8)*$Q17 -> 9.9819483 | N17: ='Omzet&Prijs'!$C$8/SUM('Omzet&Prijs'!$C$2:$C$8)*$Q17 -> 7.2853911 | O17: ='Omzet&Prijs'!$C$7/SUM('Omzet&Prijs'!$C$2:$C$8)*$Q17 -> 7.9773512 | P17: ='Omzet&Prijs'!$C$2/SUM('Omzet&Prijs'!$C$2:$C$8)*$Q17 -> 0.80620332 | Q17: =IF(F17<0,F17*-1,F17) -> 56.5
A18: Kosten | B18: Kosten | C18: Analyse | D18: Analysekosten | E18: 2010 | F18: 150 | G18: 0 | H18: 0 | I18: ='Omzet&Prijs'!$C$3/SUM('Omzet&Prijs'!$C$2:$C$8)*$Q18 -> 62.601066 | J18: ='Omzet&Prijs'!$C$4/SUM('Omzet&Prijs'!$C$2:$C$8)*$Q18 -> 16.929252 | K18: 0 | L18: ='Omzet&Prijs'!$C$6/SUM('Omzet&Prijs'!$C$2:$C$8)*$Q18 -> 1.3080172 | M18: ='Omzet&Prijs'!$C$5/SUM('Omzet&Prijs'!$C$2:$C$8)*$Q18 -> 26.500748 | N18: ='Omzet&Prijs'!$C$8/SUM('Omzet&Prijs'!$C$2:$C$8)*$Q18 -> 19.341746 | O18: ='Omzet&Prijs'!$C$7/SUM('Omzet&Prijs'!$C$2:$C$8)*$Q18 -> 21.178809 | P18: ='Omzet&Prijs'!$C$2/SUM('Omzet&Prijs'!$C$2:$C$8)*$Q18 -> 2.1403628 | Q18: =IF(F18<0,F18*-1,F18) -> 150
A19: Kosten | B19: Kosten | C19: Preventie | D19: Crisispreventie | E19: 2010 | F19: 955.79 | G19: 0 | H19: 0 | I19: ='Omzet&Prijs'!$C$3/SUM('Omzet&Prijs'!$C$2:$C$8)*$Q19 -> 398.88982 | J19: ='Omzet&Prijs'!$C$4/SUM('Omzet&Prijs'!$C$2:$C$8)*$Q19 -> 107.87207 | K19: 0 | L19: ='Omzet&Prijs'!$C$6/SUM('Omzet&Prijs'!$C$2:$C$8)*$Q19 -> 8.3345985 | M19: ='Omzet&Prijs'!$C$5/SUM('Omzet&Prijs'!$C$2:$C$8)*$Q19 -> 168.861 | N19: ='Omzet&Prijs'!$C$8/SUM('Omzet&Prijs'!$C$2:$C$8)*$Q19 -> 123.24432 | O19: ='Omzet&Prijs'!$C$7/SUM('Omzet&Prijs'!$C$2:$C$8)*$Q19 -> 134.94996 | P19: ='Omzet&Prijs'!$C$2/SUM('Omzet&Prijs'!$C$2:$C$8)*$Q19 -> 13.638249 | Q19: =IF(F19<0,F19*-1,F19) -> 955.79
A20: Kosten | B20: Kosten | C20: Fust | D20: Fustbon | E20: 2010 | F20: 0.23 | G20: 0 | H20: 0 | I20: ='Omzet&Prijs'!$C$3/SUM('Omzet&Prijs'!$C$2:$C$8)*$Q20 -> 0.095988301 | J20: ='Omzet&Prijs'!$C$4/SUM('Omzet&Prijs'!$C$2:$C$8)*$Q20 -> 0.025958186 | K20: 0 | L20: ='Omzet&Prijs'!$C$6/SUM('Omzet&Prijs'!$C$2:$C$8)*$Q20 -> 0.0020056264 | M20: ='Omzet&Prijs'!$C$5/SUM('Omzet&Prijs'!$C$2:$C$8)*$Q20 -> 0.04063448 | N20: ='Omzet&Prijs'!$C$8/SUM('Omzet&Prijs'!$C$2:$C$8)*$Q20 -> 0.029657344 | O20: ='Omzet&Prijs'!$C$7/SUM('Omzet&Prijs'!$C$2:$C$8)*$Q20 -> 0.032474173 | P20: ='Omzet&Prijs'!$C$2/SUM('Omzet&Prijs'!$C$2:$C$8)*$Q20 -> 0.0032818896 | Q20: =IF(F20<0,F20*-1,F20) -> 0.23
A21: Kosten | B21: Kosten | C21: Koelen | D21: Koelloon | E21: 2010 | F21: 10657.92 | G21: 0 | H21: 0 | I21: ='Omzet&Prijs'!$C$3/(SUM('Omzet&Prijs'!$C$2:$C$8)-'Omzet&Prijs'!$C$7)*$Q21 -> 5179.2499 | J21: ='Omzet&Prijs'!$C$4/(SUM('Omzet&Prijs'!$C$2:$C$8)-'Omzet&Prijs'!$C$7)*$Q21 -> 1400.6284 | K21: 0 | L21: ='Omzet&Prijs'!$C$6/(SUM('Omzet&Prijs'!$C$2:$C$8)-'Omzet&Prijs'!$C$7)*$Q21 -> 108.21778 | M21: ='Omzet&Prijs'!$C$5/(SUM('Omzet&Prijs'!$C$2:$C$8)-'Omzet&Prijs'!$C$7)*$Q21 -> 2192.5185 | N21: ='Omzet&Prijs'!$C$8/(SUM('Omzet&Prijs'!$C$2:$C$8)-'Omzet&Prijs'!$C$7)*$Q21 -> 1600.2242 | O21: 0 | P21: ='Omzet&Prijs'!$C$2/(SUM('Omzet&Prijs'!$C$2:$C$8)-'Omzet&Prijs'!$C$7)*$Q21 -> 177.08123 | Q21: =IF(F21<0,F21*-1,F21) -> 10657.92
A22: Kosten | B22: Kosten | C22: Algemeen Junami | D22: Kosten Junami | E22: 2010 | F22: 1722.51 | G22: 0 | H22: 0 | I22: 0 | J22: 0 | K22: 0 | L22: 0 | M22: 0 | N22: =Q22 -> 1722.51 | O22: 0 | P22: 0 | Q22: =IF(F22<0,F22*-1,F22) -> 1722.51
A23: Kosten | B23: Kosten | C23: Algemeen | D23: Onvoorziene kosten | E23: 2010 | F23: 449.51 | G23: 0 | H23: 0 | I23: ='Omzet&Prijs'!$C$3/SUM('Omzet&Prijs'!$C$2:$C$8)*$Q23 -> 187.5987 | J23: ='Omzet&Prijs'!$C$4/SUM('Omzet&Prijs'!$C$2:$C$8)*$Q23 -> 50.732454 | K23: 0 | L23: ='Omzet&Prijs'!$C$6/SUM('Omzet&Prijs'!$C$2:$C$8)*$Q23 -> 3.9197788 | M23: ='Omzet&Prijs'!$C$5/SUM('Omzet&Prijs'!$C$2:$C$8)*$Q23 -> 79.415674 | N23: ='Omzet&Prijs'!$C$8/SUM('Omzet&Prijs'!$C$2:$C$8)*$Q23 -> 57.962056 | O23: ='Omzet&Prijs'!$C$7/SUM('Omzet&Prijs'!$C$2:$C$8)*$Q23 -> 63.467241 | P23: ='Omzet&Prijs'!$C$2/SUM('Omzet&Prijs'!$C$2:$C$8)*$Q23 -> 6.4140965 | Q23: =IF(F23<0,F23*-1,F23) -> 449.51
A24: Kosten | B24: Opbrengsten | C24: Bonus | D24: Resultaatbonus | E24: 2010 | F24: -3257.52 | Q24: =IF(F24<0,F24*-1,F24) -> 3257.52
A25: Kosten | B25: Kosten | C25: Sorteren | D25: Sorteerkosten | E25: 2010 | F25: =5774.79+958.97 -> 6733.76 | G25: 0 | H25: 0 | I25: ='Omzet&Prijs'!$C$3/(SUM('Omzet&Prijs'!$C$2:$C$8)-'Omzet&Prijs'!$C$7)*$Q25 -> 3272.292 | J25: ='Omzet&Prijs'!$C$4/(SUM('Omzet&Prijs'!$C$2:$C$8)-'Omzet&Prijs'!$C$7)*$Q25 -> 884.92832 | K25: 0 | L25: ='Omzet&Prijs'!$C$6/(SUM('Omzet&Prijs'!$C$2:$C$8)-'Omzet&Prijs'!$C$7)*$Q25 -> 68.372865 | M25: ='Omzet&Prijs'!$C$5/(SUM('Omzet&Prijs'!$C$2:$C$8)-'Omzet&Prijs'!$C$7)*$Q25 -> 1385.2509 | N25: ='Omzet&Prijs'!$C$8/(SUM('Omzet&Prijs'!$C$2:$C$8)-'Omzet&Prijs'!$C$7)*$Q25 -> 1011.0346 | O25: 0 | P25: ='Omzet&Prijs'!$C$2/(SUM('Omzet&Prijs'!$C$2:$C$8)-'Omzet&Prijs'!$C$7)*$Q25 -> 111.88135 | Q25: =IF(F25<0,F25*-1,F25) -> 6733.76
A26: Kosten | B26: Balans | C26: Etiketteren | D26: Stikkeren | E26: 2010 | F26: -733.8 | Q26: =IF(F26<0,F26*-1,F26) -> 733.8
A27: Kosten | B27: Kosten | C27: Algemeen | D27: Touw | E27: 2010 | F27: 53.75 | G27: 0 | H27: 0 | I27: ='Omzet&Prijs'!$C$3/SUM('Omzet&Prijs'!$C$2:$C$8)*$Q27 -> 22.432049 | J27: ='Omzet&Prijs'!$C$4/SUM('Omzet&Prijs'!$C$2:$C$8)*$Q27 -> 6.0663153 | K27: 0 | L27: ='Omzet&Prijs'!$C$6/SUM('Omzet&Prijs'!$C$2:$C$8)*$Q27 -> 0.46870617 | M27: ='Omzet&Prijs'!$C$5/SUM('Omzet&Prijs'!$C$2:$C$8)*$Q27 -> 9.4961013 | N27: ='Omzet&Prijs'!$C$8/SUM('Omzet&Prijs'!$C$2:$C$8)*$Q27 -> 6.9307924 | O27: ='Omzet&Prijs'!$C$7/SUM('Omzet&Prijs'!$C$2:$C$8)*$Q27 -> 7.589073 | P27: ='Omzet&Prijs'!$C$2/SUM('Omzet&Prijs'!$C$2:$C$8)*$Q27 -> 0.76696333 | Q27: =IF(F27<0,F27*-1,F27) -> 53.75
A28: Kosten | B28: Kosten | C28: Zorgsystemen | D28: Zorgsystemen | E28: 2010 | F28: 250 | G28: 0 | H28: 0 | I28: ='Omzet&Prijs'!$C$3/SUM('Omzet&Prijs'!$C$2:$C$8)*$Q28 -> 104.33511 | J28: ='Omzet&Prijs'!$C$4/SUM('Omzet&Prijs'!$C$2:$C$8)*$Q28 -> 28.21542 | K28: 0 | L28: ='Omzet&Prijs'!$C$6/SUM('Omzet&Prijs'!$C$2:$C$8)*$Q28 -> 2.1800287 | M28: ='Omzet&Prijs'!$C$5/SUM('Omzet&Prijs'!$C$2:$C$8)*$Q28 -> 44.167913 | N28: ='Omzet&Prijs'!$C$8/SUM('Omzet&Prijs'!$C$2:$C$8)*$Q28 -> 32.236244 | O28: ='Omzet&Prijs'!$C$7/SUM('Omzet&Prijs'!$C$2:$C$8)*$Q28 -> 35.298014 | P28: ='Omzet&Prijs'!$C$2/SUM('Omzet&Prijs'!$C$2:$C$8)*$Q28 -> 3.5672713 | Q28: =IF(F28<0,F28*-1,F28) -> 250
A29: Kosten | B29: Balans | C29: BTW | D29: BTW | E29: 2010 | F29: =175.11+-9404.32 -> -9229.21 | Q29: =IF(F29<0,F29*-1,F29) -> 9229.21
A30: Aanvoer | B30: Opbrengsten | C30: Omzet | D30: Productomzet | E30: 2011 | F30: -151790.75 | Q30: =IF(F30<0,F30*-1,F30) -> 151790.75
A31: Aanvoer | B31: Balans | C31: Fust | D31: Fust eenmalig | E31: 2011 | F31: -6136.23 | Q31: =IF(F31<0,F31*-1,F31) -> 6136.23
A32: Aanvoer | B32: Balans | C32: Fust | D32: Fust meermalig | E32: 2011 | F32: -43148.4 | Q32: =IF(F32<0,F32*-1,F32) -> 43148.4
A33: Aanvoer | B33: Balans | C33: Fust | D33: Fust huur terugbet. | E33: 2011 | F33: -2802.35 | Q33: =IF(F33<0,F33*-1,F33) -> 2802.35
A34: Aanvoer | B34: Balans | C34: Verpakking | D34: Verpakkingskosten | E34: 2011 | F34: -953.8 | Q34: =IF(F34<0,F34*-1,F34) -> 953.8
A35: Aanvoer | B35: Balans | C35: Pallet | D35: Pallet eenmalig | E35: 2011 | F35: -890.12 | Q35: =IF(F35<0,F35*-1,F35) -> 890.12
A36: Aanvoer | B36: Balans | C36: Pallet | D36: Pallet meermalig | E36: 2011 | F36: -2109.55 | Q36: =IF(F36<0,F36*-1,F36) -> 2109.55
A37: Aanvoer | B37: Kosten | C37: Productheffing | D37: Productheffing | E37: 2011 | F37: 1183.42 | G37: 0 | H37: ='Omzet&Prijs'!$C$15/SUM('Omzet&Prijs'!$C$9:$C$16)*$Q37 -> 1.026631 | I37: ='Omzet&Prijs'!$C$10/SUM('Omzet&Prijs'!$C$9:$C$16)*$Q37 -> 267.92084 | J37: ='Omzet&Prijs'!$C$11/SUM('Omzet&Prijs'!$C$9:$C$16)*$Q37 -> 151.56807 | K37: 0 | L37: ='Omzet&Prijs'!$C$12/SUM('Omzet&Prijs'!$C$9:$C$16)*$Q37 -> 212.29983 | M37: ='Omzet&Prijs'!$C$13/SUM('Omzet&Prijs'!$C$9:$C$16)*$Q37 -> 48.895637 | N37: ='Omzet&Prijs'!$C$16/SUM('Omzet&Prijs'!$C$9:$C$16)*$Q37 -> 174.7158 | O37: ='Omzet&Prijs'!$C$14/SUM('Omzet&Prijs'!$C$9:$C$16)*$Q37 -> 300.03012 | P37: ='Omzet&Prijs'!$C$9/SUM('Omzet&Prijs'!$C$9:$C$16)*$Q37 -> 26.963064 | Q37: =IF(F37<0,F37*-1,F37) -> 1183.42
A38: Aanvoer | B38: Kosten | C38: Provisie | D38: Provisie lid | E38: 2011 | F38: =4537.84+2136.24 -> 6674.08 | G38: 0 | H38: ='Omzet&Prijs'!$C$15/SUM('Omzet&Prijs'!$C$9:$C$16)*$Q38 -> 5.7898444 | I38: ='Omzet&Prijs'!$C$10/SUM('Omzet&Prijs'!$C$9:$C$16)*$Q38 -> 1510.981 | J38: ='Omzet&Prijs'!$C$11/SUM('Omzet&Prijs'!$C$9:$C$16)*$Q38 -> 854.79158 | K38: 0 | L38: ='Omzet&Prijs'!$C$12/SUM('Omzet&Prijs'!$C$9:$C$16)*$Q38 -> 1197.2977 | M38: ='Omzet&Prijs'!$C$13/SUM('Omzet&Prijs'!$C$9:$C$16)*$Q38 -> 275.7545 | N38: ='Omzet&Prijs'!$C$16/SUM('Omzet&Prijs'!$C$9:$C$16)*$Q38 -> 985.33678 | O38: ='Omzet&Prijs'!$C$14/SUM('Omzet&Prijs'!$C$9:$C$16)*$Q38 -> 1692.0662 | P38: ='Omzet&Prijs'!$C$9/SUM('Omzet&Prijs'!$C$9:$C$16)*$Q38 -> 152.06237 | Q38: =IF(F38<0,F38*-1,F38) -> 6674.08
A39: Aanvoer | B39: Kosten | C39: Royalty Junami | D39: Royaltykst Junami | E39: 2011 | F39: 234.02 | G39: 0 | H39: 0 | I39: 0 | J39: 0 | K39: 0 | L39: 0 | M39: 0 | N39: =Q39 -> 234.02 | O39: 0 | P39: 0 | Q39: =IF(F39<0,F39*-1,F39) -> 234.02
A40: Aanvoer | B40: Kosten | C40: Promotie Junami | D40: Promotiekst Junami | E40: 2011 | F40: 1404.03 | G40: 0 | H40: 0 | I40: 0 | J40: 0 | K40: 0 | L40: 0 | M40: 0 | N40: =Q40 -> 1404.03 | O40: 0 | P40: 0 | Q40: =IF(F40<0,F40*-1,F40) -> 1404.03
...

Sheet Omzet&Prijs
A1: Boekjaar | B1: Ras | C1: Hoeveelheid (kg) | D1: Omzet | E1: Prijs per kg.
A2: 2010 | B2: Milwa | C2: 6709 | D2: 1582.415 | E2: =D2/C2 -> 0.23586451 | G2: Het ras Milwa is de 2de klasse van Junami hoort dus bij Junami.
A3: 2010 | B3: Elstar | C3: 196224 | D3: 82199.9 | E3: =D3/C3 -> 0.41890849 | G3: Het ras jonagored is jonagold
A4: 2010 | B4: Golden | C4: 53065 | D4: 17030.827 | E4: =D4/C4 -> 0.32094275
A5: 2010 | B5: Jonagored | C5: 83067 | D5: 29570.305 | E5: =D5/C5 -> 0.35598138
A6: 2010 | B6: Jonagold | C6: 4100 | D6: 1633.8 | E6: =D6/C6 -> 0.3984878
A7: 2010 | B7: kroet/industrie appels | C7: 66385.3 | D7: 6496.519 | E7: =D7/C7 -> 0.097860807
A8: 2010 | B8: Junami | C8: 60627 | D8: 53264.018 | E8: =D8/C8 -> 0.87855276
A9: 2011 | B9: Milwa | C9: 7222.5 | D9: 2976.425 | E9: =D9/C9 -> 0.41210453
A10: 2011 | B10: Elstar | C10: 71767 | D10: 39141.241 | E10: =D10/C10 -> 0.5453933
A11: 2011 | B11: Golden | C11: 40600 | D11: 20415.366 | E11: =D11/C11 -> 0.50284153
A12: 2011 | B12: Jonagored | C12: 56868 | D12: 28508.649 | E12: =D12/C12 -> 0.50131267
A13: 2011 | B13: Jonagold | C13: 13097.5 | D13: 2451.4 | E13: =D13/C13 -> 0.18716549
A14: 2011 | B14: kroet/industrie appels | C14: 80368 | D14: 13457.964 | E14: =D14/C14 -> 0.16745426
A15: 2011 | B15: Delcorf | C15: 275 | D15: 173.25 | E15: =D15/C15 -> 0.63
... A57: 2017 | B57: kroet/industrie appels | C57: 61636 | D57: 9365.036 | E57: =D57/C57 -> 0.15194101

Sheet Loonkosten
A1: Omschrijving | B1: Boekjaar | C1: Loonkosten
A2: brutoloon | B2: 2010 | C2: 13585
A3: vergoeding premie ZVW | B3: 2010 | C3: 942
A4: sociale lasten | B4: 2010 | C4: 650
A5: brutoloon | B5: 2011 | C5: 34086
A6: vergoeding premie ZVW | B6: 2011 | C6: 2609
A7: sociale lasten | B7: 2011 | C7: 2634
A8: brutoloon | B8: 2012 | C8: 22567
A9: vergoeding premie ZVW | B9: 2012 | C9: 1593
A10: sociale lasten | B10: 2012 | C10: 899
A11: brutoloon | B11: 2013 | C11: 27781
A12: vergoeding premie ZVW | B12: 2013 | C12: 2160
A13: sociale lasten | B13: 2013 | C13: 2415
... A22: sociale lasten | B22: 2016 | C22: 3909

Sheet Rassen
A1: Ras
A2: Breaburn
A3: Delcorf
A4: Elstar
A5: Golden
A6: Joly-Red
A7: Jonagold
A8: Jonagored
A9: Junami
A10: kroet/industrie appels
A11: Milwa
